Workbook
Name _______________________________________________________________________________wwp1: #REF!
Name _______________________________________________________________________________wwp2: #REF!
Name ______________________________________________________________________________wwp1: #REF!
Name ______________________________________________________________________________wwp2: #REF!
Name _____________________________________________________________________________wwp1: #REF!
Name _____________________________________________________________________________wwp2: #REF!
Name ____________________________________________________________________________wwp1: #REF!
Name ____________________________________________________________________________wwp2: #REF!
Name ___________________________________________________________________________wwp1: #REF!
Name ___________________________________________________________________________wwp2: #REF!
Name __________________________________________________________________________wwp1: #REF!
Name __________________________________________________________________________wwp2: #REF!
Name _________________________________________________________________________wwp1: #REF!
Name _________________________________________________________________________wwp2: #REF!
Name ________________________________________________________________________wwp1: #REF!
Name ________________________________________________________________________wwp2: #REF!
Name _______________________________________________________________________wwp1: #REF!
Name _______________________________________________________________________wwp2: #REF!
Name ______________________________________________________________________wwp1: #REF!
Name ______________________________________________________________________wwp2: #REF!
Name _____________________________________________________________________wwp1: #REF!
Name _____________________________________________________________________wwp2: #REF!
Name ____________________________________________________________________wwp1: #REF!
Name ____________________________________________________________________wwp2: #REF!
Name ___________________________________________________________________wwp1: #REF!
Name ___________________________________________________________________wwp2: #REF!
Name __________________________________________________________________wwp1: #REF!
Name __________________________________________________________________wwp2: #REF!
Name _________________________________________________________________wwp1: #REF!
Name _________________________________________________________________wwp2: #REF!
Name ________________________________________________________________wwp1: #REF!
Name ________________________________________________________________wwp2: #REF!
Name _______________________________________________________________wwp1: #REF!
Name _______________________________________________________________wwp2: #REF!
Name ______________________________________________________________wwp1: #REF!
Name ______________________________________________________________wwp2: #REF!
Name _____________________________________________________________wwp1: #REF!
Name _____________________________________________________________wwp2: #REF!
Name ____________________________________________________________wwp1: #REF!
Name ____________________________________________________________wwp2: #REF!
Name ___________________________________________________________wwp1: #REF!
Name ___________________________________________________________wwp2: #REF!
Name __________________________________________________________wwp1: #REF!
Name __________________________________________________________wwp2: #REF!
Name _________________________________________________________wwp1: #REF!
Name _________________________________________________________wwp2: #REF!
Name ________________________________________________________wwp1: #REF!
Name ________________________________________________________wwp2: #REF!
Name _______________________________________________________wwp1: #REF!
Name _______________________________________________________wwp2: #REF!
Name ______________________________________________________wwp1: #REF!
Name ______________________________________________________wwp2: #REF!
Name _____________________________________________________wwp1: #REF!
Name _____________________________________________________wwp2: #REF!
Name ____________________________________________________wwp1: #REF!
Name ____________________________________________________wwp2: #REF!
Name ___________________________________________________wwp1: #REF!
Name ___________________________________________________wwp2: #REF!
Name __________________________________________________wwp1: #REF!
Name __________________________________________________wwp2: #REF!

Sheet Overall Monthly
B1: Mechanical Availability (Monthly) | E1: 0 | AJ1: 0 | AK1: 0 | AL1: 0 | AM1: 1
B2: Metrics | C2: Model | D2: Fleet | E2: 46047 | F2: 46048 | G2: 46049 | H2: 46050 | I2: 46051 | J2: 46052 | K2: 46053 | L2: 46054 | M2: 46055 | N2: 46056 | O2: 46057 | P2: 46058 | Q2: 46059 | R2: 46060 | S2: 46061 | T2: 46062 | U2: 46063 | V2: 46064 | W2: 46065 | X2: 46066 | Y2: 46067 | Z2: 46068 | AA2: 46069 | AB2: 46070 | AC2: 46071 | AD2: 46072 | AE2: 46073 | AF2: 46074 | AG2: 46075 | AH2: 46076 | AI2: 46077 | AJ2: 46053 | AK2: 46081 | AL2: 46111 | AM2: 31 apr | AN2: Average | AO2: Target
A3: =C3&D3 -> 320GC - DFOverall MTD | B3: Mechanical Availability | C3: 320GC - DF | D3: Overall MTD | AJ3: 0.92807646 | AK3: 0.92807646 | AL3: 0.96230159 | AM3: =VLOOKUP(A3,Overall!B:DD,83,0) -> #N/A | AN3: =AVERAGE(AJ3:AM3) -> #N/A | AO3: 0.88
A4: =C4&D4 -> 320GC - DFOverall YTD | B4: Mechanical Availability | C4: 320GC - DF | D4: Overall YTD | AJ4: 0.94172138 | AK4: 0.94172138 | AL4: 0.9486641 | AM4: =VLOOKUP(A4,Overall!B:DD,83,0) -> #N/A | AN4: =AVERAGE(AJ4:AM4) -> #N/A | AO4: 0.88
A5: =C5&D5 -> 320GC - DFLeftover Downtime MTD (hr) | B5: Mechanical Availability | C5: 320GC - DF | D5: Leftover Downtime MTD (hr) | E5: 0 | F5: 0 | G5: 0 | H5: 0 | I5: 0 | J5: 0 | K5: 0 | L5: 0 | M5: 0 | N5: 0 | O5: 0 | P5: 0 | Q5: 0 | R5: 0 | S5: 0 | T5: 0 | U5: 0 | V5: 0 | W5: 0 | X5: 0 | Y5: 0 | Z5: 0 | AA5: 0 | AB5: 0 | AC5: 0 | AD5: 0 | AE5: 0 | AF5: 0 | AG5: 0 | AH5: 0 | AI5: 0 | AJ5: 107.30667 | AK5: 107.30667 | AL5: 165.92 | AM5: =VLOOKUP(A5,Overall!B:DD,83,0) -> #N/A | AN5: =AVERAGE(AJ5:AM5) -> #N/A | AO5: 25
A6: =C6&D6 -> 320GCOverall MTD | B6: Mechanical Availability | C6: 320GC | D6: Overall MTD | E6: #REF! | F6: #REF! | G6: #REF! | H6: #REF! | I6: #REF! | J6: #REF! | K6: #REF! | L6: #REF! | M6: #REF! | N6: #REF! | O6: #REF! | P6: #REF! | Q6: #REF! | R6: #REF! | S6: #REF! | T6: #REF! | U6: #REF! | V6: #REF! | W6: #REF! | X6: #REF! | Y6: #REF! | Z6: #REF! | AA6: #REF! | AB6: #REF! | AC6: #REF! | AD6: #REF! | AE6: #REF! | AF6: #REF! | AG6: #REF! | AH6: #REF! | AI6: #REF! | AJ6: 0.90184635 | AK6: 0.90184635 | AL6: 0.92089991 | AM6: =VLOOKUP(A6,Overall!B:DD,83,0) -> #N/A | AN6: =AVERAGE(AJ6:AM6) -> #N/A | AO6: 0.88
A7: =C7&D7 -> 320GCOverall YTD | B7: Mechanical Availability | C7: 320GC | D7: Overall YTD | E7: #REF! | F7: #REF! | G7: #REF! | H7: #REF! | I7: #REF! | J7: #REF! | K7: #REF! | L7: #REF! | M7: #REF! | N7: #REF! | O7: #REF! | P7: #REF! | Q7: #REF! | R7: #REF! | S7: #REF! | T7: #REF! | U7: #REF! | V7: #REF! | W7: #REF! | X7: #REF! | Y7: #REF! | Z7: #REF! | AA7: #REF! | AB7: #REF! | AC7: #REF! | AD7: #REF! | AE7: #REF! | AF7: #REF! | AG7: #REF! | AH7: #REF! | AI7: #REF! | AJ7: 0.90185639 | AK7: 0.90185639 | AL7: 0.90828071 | AM7: =VLOOKUP(A7,Overall!B:DD,83,0) -> #N/A | AN7: =AVERAGE(AJ7:AM7) -> #N/A | AO7: 0.88
A8: =C8&D8 -> 320GCLeftover Downtime MTD (hr) | B8: Mechanical Availability | C8: 320GC | D8: Leftover Downtime MTD (hr) | AJ8: 308.82 | AK8: 308.82 | AL8: 522.21 | AM8: =VLOOKUP(A8,Overall!B:DD,83,0) -> #N/A | AN8: =AVERAGE(AJ8:AM8) -> #N/A | AO8: 25
A9: =C9&D9 -> 330NGOverall MTD | B9: Mechanical Availability | C9: 330NG | D9: Overall MTD | E9: 0.90579459 | F9: 0.97419591 | G9: 0.97288012 | H9: 0.97446394 | I9: 0.96557018 | J9: 0.96645468 | K9: 0.95903996 | L9: 0.94842836 | M9: 0.93686495 | N9: 0.93208252 | O9: 0.92347222 | P9: 0.92019537 | Q9: 0.92242629 | R9: 0.92434492 | S9: 0.9213868 | T9: 0.92238791 | U9: 0.92324105 | V9: 0.91649037 | W9: 0.91181571 | X9: 0.91263466 | Y9: 0.90649488 | Z9: 0.90783556 | AA9: 0.90724016 | AB9: 0.90375032 | AC9: 0.90403113 | AD9: 0.90494298 | AE9: 0.90568067 | AF9: 0.90531595 | AG9: 0.90313283 | AH9: 0.90227995 | AI9: 0.90202851 | AJ9: 0.85312805 | AK9: 0.85312805 | AL9: 0.83609082 | AM9: =VLOOKUP(A9,Overall!B:DD,83,0) -> #N/A | AN9: =AVERAGE(AJ9:AM9) -> #N/A | AO9: 0.88
A10: =C10&D10 -> 330NGOverall YTD | B10: Mechanical Availability | C10: 330NG | D10: Overall YTD | E10: 0.90186937 | F10: 0.90476243 | G10: 0.90733173 | H10: 0.90993543 | I10: 0.91096948 | J10: 0.91300476 | K10: 0.91330348 | L10: 0.91238269 | M10: 0.91061826 | N10: 0.91010932 | O10: 0.90822315 | P10: 0.90762897 | Q10: 0.90872167 | R10: 0.90976618 | S10: 0.90906 | T10: 0.90976111 | U10: 0.91041804 | V10: 0.90793173 | W10: 0.90613208 | X10: 0.90662612 | Y10: 0.90397187 | Z10: 0.90465359 | AA10: 0.90443801 | AB10: 0.90278983 | AC10: 0.90295025 | AD10: 0.90343754 | AE10: 0.90385124 | AF10: 0.90369403 | AG10: 0.90254969 | AH10: 0.90209402 | AI10: 0.90195778 | AJ10: 0.81315197 | AK10: 0.81315197 | AL10: 0.82089038 | AM10: =VLOOKUP(A10,Overall!B:DD,83,0) -> #N/A | AN10: =AVERAGE(AJ10:AM10) -> #N/A | AO10: 0.88
A11: =C11&D11 -> 330NGLeftover Downtime MTD (hr) | B11: Mechanical Availability | C11: 330NG | D11: Leftover Downtime MTD (hr) | AJ11: -219.92 | AK11: -219.92 | AL11: -324.57667 | AM11: =VLOOKUP(A11,Overall!B:DD,83,0) -> #N/A | AN11: =AVERAGE(AJ11:AM11) -> #N/A | AO11: 25
A12: =C12&D12 -> 320GC - LAOverall MTD | B12: Mechanical Availability | C12: 320GC - LA | D12: Overall MTD | AJ12: 0.81599462 | AK12: 0.81599462 | AL12: 0.9176422 | AM12: =VLOOKUP(A12,Overall!B:DD,83,0) -> #N/A | AN12: =AVERAGE(AJ12:AM12) -> #N/A | AO12: 0.88
A13: =C13&D13 -> 320GC - LAOverall YTD | B13: Mechanical Availability | C13: 320GC - LA | D13: Overall YTD | AJ13: 0.85728956 | AK13: 0.85728956 | AL13: 0.87764949 | AM13: =VLOOKUP(A13,Overall!B:DD,83,0) -> #N/A | AN13: =AVERAGE(AJ13:AM13) -> #N/A | AO13: 0.88
A14: =C14&D14 -> 320GC - LALeftover Downtime MTD (hr) | B14: Mechanical Availability | C14: 320GC - LA | D14: Leftover Downtime MTD (hr) | AJ14: -142.86 | AK14: -142.86 | AL14: 75.886667 | AM14: =VLOOKUP(A14,Overall!B:DD,83,0) -> #N/A | AN14: =AVERAGE(AJ14:AM14) -> #N/A | AO14: 25
A15: =C15&D15 -> 777D/EOverall MTD | B15: Mechanical Availability | C15: 777D/E | D15: Overall MTD | AJ15: 0.8421 | AK15: 0.87813927 | AL15: 0.84464286 | AM15: =VLOOKUP(A15,Overall!B:DD,83,0) -> #N/A | AN15: =AVERAGE(AJ15:AM15) -> #N/A | AO15: 0.88
A16: =C16&D16 -> KDP & FKROverall YTD | B16: Mechanical Availability | C16: KDP & FKR | D16: Overall YTD | AJ16: =AJ15 -> 0.8421 | AK16: =AVERAGE(AJ15:AK15) -> 0.86011963 | AL16: 0.87374323 | AM16: =VLOOKUP(A16,Overall!B:DD,83,0) -> #N/A | AN16: =AVERAGE(AJ16:AM16) -> #N/A | AO16: 0.88
A17: =C17&D17 -> KDP & FKRLeftover Downtime MTD (hr) | B17: Mechanical Availability | C17: KDP & FKR | D17: Leftover Downtime MTD (hr) | AJ17: -20 | AK17: -6.52 | AL17: -118.8 | AM17: =VLOOKUP(A17,Overall!B:DD,83,0) -> #N/A | AN17: =AVERAGE(AJ17:AM17) -> #N/A | AO17: 25
A18: =C18&D18 -> 777Overall MTD | B18: Mechanical Availability | C18: 777 | D18: Overall MTD | AJ18: 0.889 | AK18: 0.92237903 | AL18: 0.89174107 | AM18: =VLOOKUP(A18,Overall!B:DD,83,0) -> #N/A | AN18: =AVERAGE(AJ18:AM18) -> #N/A | AO18: 0.88
A19: =C19&D19 -> 7W8Overall YTD | B19: Mechanical Availability | C19: 7W8 | D19: Overall YTD | AJ19: =AJ18 -> 0.889 | AK19: 0.89299242 | AL19: 0.89257028 | AM19: =VLOOKUP(A19,Overall!B:DD,83,0) -> #N/A | AN19: =AVERAGE(AJ19:AM19) -> #N/A | AO19: 0.88
A20: =C20&D20 -> 7W8Leftover Downtime MTD (hr) | C20: 7W8 | D20: Leftover Downtime MTD (hr) | AJ20: 92 | AK20: 126.12 | AL20: 31.56 | AM20: =VLOOKUP(A20,Overall!B:DD,83,0) -> #N/A | AN20: =AVERAGE(AJ20:AM20) -> #N/A | AO20: 25
A21: =C21&D21 -> 6020Overall MTD | B21: Mechanical Availability | C21: 6020 | D21: Overall MTD | AJ21: 0.851 | AK21: 0.9419 | AL21: =1-(44/(24*31)) -> 0.94086022 | AM21: =VLOOKUP(A21,Overall!B:DD,83,0) -> #N/A | AN21: =AVERAGE(AJ21:AM21) -> #N/A | AO21: 0.88
A22: =C22&D22 -> 7W8Overall YTD | B22: Mechanical Availability | C22: 7W8 | D22: Overall YTD | AJ22: =AJ21 -> 0.851 | AK22: =AVERAGE(AJ21:AK21) -> 0.89645 | AL22: =AVERAGE(AJ21:AL21) -> 0.91125341 | AM22: =VLOOKUP(A22,Overall!B:DD,83,0) -> #N/A | AN22: =AVERAGE(AJ22:AM22) -> #N/A | AO22: 0.88
A23: =C23&D23 -> 7W8Leftover Downtime MTD (hr) | C23: 7W8 | D23: Leftover Downtime MTD (hr) | AJ23: =-(24*30*3%) -> -21.6 | AK23: 36.2 | AL23: 41.11 | AM23: =VLOOKUP(A23,Overall!B:DD,83,0) -> #N/A | AN23: =AVERAGE(AJ23:AM23) -> #N/A | AO23: 25
B27: Reliability (Monthly)
B28: Metrics | C28: Model | D28: Fleet | E28: 46047 | F28: 46048 | G28: 46049 | H28: 46050 | I28: 46051 | J28: 46052 | K28: 46053 | L28: 46054 | M28: 46055 | N28: 46056 | O28: 46057 | P28: 46058 | Q28: 46059 | R28: 46060 | S28: 46061 | T28: 46062 | U28: 46063 | V28: 46064 | W28: 46065 | X28: 46066 | Y28: 46067 | Z28: 46068 | AA28: 46069 | AB28: 46070 | AC28: 46071 | AD28: 46072 | AE28: 46073 | AF28: 46074 | AG28: 46075 | AH28: 46076 | AI28: 46077 | AJ28: 46047 | AK28: 46078 | AL28: 46106 | AM28: 46119 | AN28: Average | AO28: Target | AP28: Remarks
A29: 1 | B29: Reliability | C29: 320GC-DF | D29: MTBS | AJ29: 127.6061 | AK29: 89.174717 | AL29: 88.356889 | AM29: 81.004517 | AN29: =AVERAGE(AJ29:AM29) -> 96.535555 | AO29: 60 | AP29: MTTR too high
A30: 2 | C30: =C29 -> 320GC-DF | D30: MTTR | AJ30: 13.061905 | AK30: 12.175 | AL30: 12.574074 | AM30: 29.496667 | AN30: =AVERAGE(AJ30:AM30) -> 16.826911 | AO30: 8
A31: 3 | C31: 320GC | D31: MTBS | E31: #REF! | F31: #REF! | G31: #REF! | H31: #REF! | I31: #REF! | J31: #REF! | K31: #REF! | L31: #REF! | M31: #REF! | N31: #REF! | O31: #REF! | P31: #REF! | Q31: #REF! | R31: #REF! | S31: #REF! | T31: #REF! | U31: #REF! | V31: #REF! | W31: #REF! | X31: #REF! | Y31: #REF! | Z31: #REF! | AA31: #REF! | AB31: #REF! | AC31: #REF! | AD31: #REF! | AE31: #REF! | AF31: #REF! | AG31: #REF! | AH31: #REF! | AI31: #REF! | AJ31: 77.146633 | AK31: 100.24359 | AL31: 79.948136 | AM31: 138.7989 | AN31: =AVERAGE(AJ31:AM31) -> 99.034315 | AO31: 60 | AP31: MTTR too high
A32: 4 | C32: =C31 -> 320GC | D32: MTTR | E32: #REF! | F32: #REF! | G32: #REF! | H32: #REF! | I32: #REF! | J32: #REF! | K32: #REF! | L32: #REF! | M32: #REF! | N32: #REF! | O32: #REF! | P32: #REF! | Q32: #REF! | R32: #REF! | S32: #REF! | T32: #REF! | U32: #REF! | V32: #REF! | W32: #REF! | X32: #REF! | Y32: #REF! | Z32: #REF! | AA32: #REF! | AB32: #REF! | AC32: #REF! | AD32: #REF! | AE32: #REF! | AF32: #REF! | AG32: #REF! | AH32: #REF! | AI32: #REF! | AJ32: 18.147667 | AK32: 18.980556 | AL32: 15.183735 | AM32: 10.98125 | AN32: =AVERAGE(AJ32:AM32) -> 15.823302 | AO32: 8
A33: 5 | C33: 330NG | D33: MTBS | E33: 0.90579459 | F33: 0.97419591 | G33: 0.97288012 | H33: 0.97446394 | I33: 0.96557018 | J33: 0.96645468 | K33: 0.95903996 | L33: 0.94842836 | M33: 0.93686495 | N33: 0.93208252 | O33: 0.92347222 | P33: 0.92019537 | Q33: 0.92242629 | R33: 0.92434492 | S33: 0.9213868 | T33: 0.92238791 | U33: 0.92324105 | V33: 0.91649037 | W33: 0.91181571 | X33: 0.91263466 | Y33: 0.90649488 | Z33: 0.90783556 | AA33: 0.90724016 | AB33: 0.90375032 | AC33: 0.90403113 | AD33: 0.90494298 | AE33: 0.90568067 | AF33: 0.90531595 | AG33: 0.90313283 | AH33: 0.90227995 | AI33: 0.90202851 | AJ33: 59.444195 | AK33: 66.150029 | AL33: 66.684858 | AM33: 166.6689 | AN33: =AVERAGE(AJ33:AM33) -> 89.736995 | AO33: 60 | AP33: MTTR too high
A34: 6 | C34: =C33 -> 330NG | D34: MTTR | E34: 0.90186937 | F34: 0.90476243 | G34: 0.90733173 | H34: 0.90993543 | I34: 0.91096948 | J34: 0.91300476 | K34: 0.91330348 | L34: 0.91238269 | M34: 0.91061826 | N34: 0.91010932 | O34: 0.90822315 | P34: 0.90762897 | Q34: 0.90872167 | R34: 0.90976618 | S34: 0.90906 | T34: 0.90976111 | U34: 0.91041804 | V34: 0.90793173 | W34: 0.90613208 | X34: 0.90662612 | Y34: 0.90397187 | Z34: 0.90465359 | AA34: 0.90443801 | AB34: 0.90278983 | AC34: 0.90295025 | AD34: 0.90343754 | AE34: 0.90385124 | AF34: 0.90369403 | AG34: 0.90254969 | AH34: 0.90209402 | AI34: 0.90195778 | AJ34: 30.443137 | AK34: 20.129023 | AL34: 27.484 | AM34: 19.572727 | AN34: =AVERAGE(AJ34:AM34) -> 24.407222 | AO34: 8
A35: 7 | C35: 320GC-LA | D35: MTBS | AJ35: 68.278359 | AK35: 76.136841 | AL35: 72.764018 | AM35: 181.7046 | AN35: =AVERAGE(AJ35:AM35) -> 99.720954 | AO35: 60 | AP35: MTTR too high
A36: 8 | C36: =C35 -> 320GC-LA | D36: MTTR | AJ36: 10.980833 | AK36: 28.916667 | AL36: 9.3511111 | AM36: 40.455556 | AN36: =AVERAGE(AJ36:AM36) -> 22.426042 | AO36: 8
A37: 9 | C37: 777D/E | D37: MTBS | AJ37: 34.004379 | AK37: 36.814135 | AL37: 29.232353 | AM37: 77.2891 | AN37: =AVERAGE(AJ37:AM37) -> 44.334992 | AO37: 60 | AP37: MTBS too low
A38: 10 | C38: =C37 -> 777D/E | D38: MTTR | AJ38: 8.7902439 | AK38: 5.1497619 | AL38: 6.3036325 | AM38: 10.387255 | AN38: =AVERAGE(AJ38:AM38) -> 7.6577233 | AO38: 8
A39: 11 | C39: 777 | D39: MTBS | AJ39: 47.313615 | AK39: 73.559842 | AL39: 41.084932 | AM39: 76.435418 | AN39: =AVERAGE(AJ39:AM39) -> 59.598452 | AO39: 60 | AP39: Good
A40: 12 | C40: =C39 -> 777 | D40: MTTR | AJ40: 7.8046512 | AK40: 8.7666667 | AL40: 7.4801587 | AM40: 3.7166667 | AN40: =AVERAGE(AJ40:AM40) -> 6.9420358 | AO40: 8
A41: 13 | C41: 6020 | D41: MTBS | AJ41: 17.935719 | AK41: 32.417498 | AL41: 30.530349 | AM41: 21.125 | AN41: =AVERAGE(AJ41:AM41) -> 25.502141 | AO41: 60 | AP41: MTBS too low
C42: =C41 -> 6020 | D42: MTTR | AJ42: 6.4325 | AK42: 3.7928571 | AL42: 1.6083333 | AM42: 2.31875 | AN42: =AVERAGE(AJ42:AM42) -> 3.5381101 | AO42: 8
B44: MTTR: Lower better
...

Sheet Overall
F1: 3 | AJ1: 0 | AK1: 3 | BL1: 0 | BM1: 3 | CQ1: 0 | CR1: 3 | DU1: 0 | DV1: 3 | FU1: 1
C2: Mechanical Availability - Rental OHT (MTD) | F2: =WEEKNUM(F3) -> 1 | G2: =WEEKNUM(G3) -> 1 | H2: =WEEKNUM(H3) -> 1 | I2: =WEEKNUM(I3) -> 2 | J2: =WEEKNUM(J3) -> 2 | K2: =WEEKNUM(K3) -> 2 | L2: =WEEKNUM(L3) -> 2 | M2: =WEEKNUM(M3) -> 2 | ... OZ2: =WEEKNUM(OZ3) -> 8
A3: check | C3: Metrics | D3: MTD PA | E3: Fleet | F3: 46023 | G3: =F3+1 -> 46024 | H3: =G3+1 -> 46025 | I3: =H3+1 -> 46026 | J3: =I3+1 -> 46027 | K3: =J3+1 -> 46028 | L3: =K3+1 -> 46029 | M3: =L3+1 -> 46030 | N3: =M3+1 -> 46031 | ... OZ3: =OY3+1 -> 46433
A4: =ISODD(B4) -> TRUE | B4: 1 | C4: Mechanical Availability | D4: 777E Expro | E4: RT401 | F4: =IF('All Fleet'!C40="","",'All Fleet'!C40) -> 1 | G4: =IF('All Fleet'!D40="","",'All Fleet'!D40) -> 1 | H4: =IF('All Fleet'!E40="","",'All Fleet'!E40) -> 0.96666667 | I4: =IF('All Fleet'!F40="","",'All Fleet'!F40) -> 0.975 | J4: =IF('All Fleet'!G40="","",'All Fleet'!G40) -> 0.98 | K4: =IF('All Fleet'!H40="","",'All Fleet'!H40) -> 0.93319444 | L4: =IF('All Fleet'!I40="","",'All Fleet'!I40) -> 0.9339881 | M4: =IF('All Fleet'!J40="","",'All Fleet'!J40) -> 0.80421875 | ... OZ4: =IF('All Fleet'!OW40="","",'All Fleet'!OW40)
A5: =ISODD(B5) -> FALSE | B5: 2 | C5: =C4 -> Mechanical Availability | D5: =D4 -> 777E Expro | E5: RT403 | F5: =IF('All Fleet'!C41="","",'All Fleet'!C41) -> 1 | G5: =IF('All Fleet'!D41="","",'All Fleet'!D41) -> 1 | H5: =IF('All Fleet'!E41="","",'All Fleet'!E41) -> 1 | I5: =IF('All Fleet'!F41="","",'All Fleet'!F41) -> 1 | J5: =IF('All Fleet'!G41="","",'All Fleet'!G41) -> 1 | K5: =IF('All Fleet'!H41="","",'All Fleet'!H41) -> 1 | L5: =IF('All Fleet'!I41="","",'All Fleet'!I41) -> 1 | M5: =IF('All Fleet'!J41="","",'All Fleet'!J41) -> 1 | ... OZ5: =IF('All Fleet'!OW41="","",'All Fleet'!OW41)
A6: =ISODD(B6) -> TRUE | B6: 3 | C6: =C5 -> Mechanical Availability | D6: =D5 -> 777E Expro | E6: RT404 | F6: =IF('All Fleet'!C42="","",'All Fleet'!C42) -> 1 | G6: =IF('All Fleet'!D42="","",'All Fleet'!D42) -> 1 | H6: =IF('All Fleet'!E42="","",'All Fleet'!E42) -> 1 | I6: =IF('All Fleet'!F42="","",'All Fleet'!F42) -> 1 | J6: =IF('All Fleet'!G42="","",'All Fleet'!G42) -> 1 | K6: =IF('All Fleet'!H42="","",'All Fleet'!H42) -> 1 | L6: =IF('All Fleet'!I42="","",'All Fleet'!I42) -> 1 | M6: =IF('All Fleet'!J42="","",'All Fleet'!J42) -> 1 | ... OZ6: =IF('All Fleet'!OW42="","",'All Fleet'!OW42)
A7: =ISODD(B7) -> FALSE | B7: 4 | C7: =C6 -> Mechanical Availability | D7: =D6 -> 777E Expro | E7: RT405 | F7: =IF('All Fleet'!C43="","",'All Fleet'!C43) -> 1 | G7: =IF('All Fleet'!D43="","",'All Fleet'!D43) -> 1 | H7: =IF('All Fleet'!E43="","",'All Fleet'!E43) -> 1 | I7: =IF('All Fleet'!F43="","",'All Fleet'!F43) -> 1 | J7: =IF('All Fleet'!G43="","",'All Fleet'!G43) -> 1 | K7: =IF('All Fleet'!H43="","",'All Fleet'!H43) -> 1 | L7: =IF('All Fleet'!I43="","",'All Fleet'!I43) -> 1 | M7: =IF('All Fleet'!J43="","",'All Fleet'!J43) -> 1 | ... OZ7: =IF('All Fleet'!OW43="","",'All Fleet'!OW43)
A8: =ISODD(B8) -> TRUE | B8: 5 | C8: =C7 -> Mechanical Availability | D8: =D7 -> 777E Expro | E8: RT410 | F8: =IF('All Fleet'!C44="","",'All Fleet'!C44) -> 1 | G8: =IF('All Fleet'!D44="","",'All Fleet'!D44) -> 1 | H8: =IF('All Fleet'!E44="","",'All Fleet'!E44) -> 1 | I8: =IF('All Fleet'!F44="","",'All Fleet'!F44) -> 1 | J8: =IF('All Fleet'!G44="","",'All Fleet'!G44) -> 1 | K8: =IF('All Fleet'!H44="","",'All Fleet'!H44) -> 1 | L8: =IF('All Fleet'!I44="","",'All Fleet'!I44) -> 1 | M8: =IF('All Fleet'!J44="","",'All Fleet'!J44) -> 1 | ... OZ8: =IF('All Fleet'!OW44="","",'All Fleet'!OW44)
A9: =ISODD(B9) -> FALSE | B9: 6 | C9: =C8 -> Mechanical Availability | D9: =D8 -> 777E Expro | E9: Overall Weekly | F9: =IF(F8="","",AVERAGE($F$4:$H$8)) -> 0.99777778 | G9: =IF(G8="","",AVERAGE($F$4:$H$8)) -> 0.99777778 | H9: =IF(H8="","",AVERAGE($F$4:$H$8)) -> 0.99777778 | I9: =IF(I8="","",AVERAGE($I4:I8)) -> 0.995 | J9: =IF(J8="","",AVERAGE($I4:J8)) -> 0.9955 | K9: =IF(K8="","",AVERAGE($I4:K8)) -> 0.9925463 | L9: =IF(L8="","",AVERAGE($I4:L8)) -> 0.99110913 | M9: =IF(M8="","",AVERAGE($I4:M8)) -> 0.98505605 | N9: =IF(N8="","",AVERAGE($I4:N8)) -> 0.98155288 | O9: =IF(O8="","",AVERAGE($I4:O8)) -> 0.97858461 | P9: =IF(P8="","",AVERAGE($P4:P8)) -> 0.93678788 | Q9: =IF(Q8="","",AVERAGE($P4:Q8)) -> 0.93643561 | R9: =IF(R8="","",AVERAGE($P4:R8)) -> 0.9288075 | S9: =IF(S8="","",AVERAGE($P4:S8)) -> 0.92653717 | T9: =IF(T8="","",AVERAGE($P4:T8)) -> 0.92552863 | U9: =IF(U8="","",AVERAGE($P4:U8)) -> 0.92306031 | V9: =IF(V8="","",AVERAGE($P4:V8)) -> 0.92197607 | W9: =IF(W8="","",AVERAGE($W4:W8)) -> 0.91765278 | X9: =IF(X8="","",AVERAGE($W4:X8)) -> 0.9191027 | Y9: =IF(Y8="","",AVERAGE($W4:Y8)) -> 0.91899764 | Z9: =IF(Z8="","",AVERAGE($W4:Z8)) -> 0.91989009 | AA9: =IF(AA8="","",AVERAGE($W4:AA8)) -> 0.91916283 | AB9: =IF(AB8="","",AVERAGE($W4:AB8)) -> 0.91593038 | AC9: =IF(AC8="","",AVERAGE($W4:AC8)) -> 0.91375183 | AD9: =IF(AD8="","",AVERAGE($AD4:AD8)) -> 0.90347 | AE9: =IF(AE8="","",AVERAGE($AD4:AE8)) -> 0.90532635 | AF9: =IF(AF8="","",AVERAGE($AD4:AF8)) -> 0.90697168 | AG9: =IF(AG8="","",AVERAGE($AD4:AG8)) -> 0.90543337 | AH9: =IF(AH8="","",AVERAGE($AD4:AH8)) -> 0.9051944 | AI9: =IF(AI8="","",AVERAGE($AD4:AI8)) -> 0.904862 | AJ9: =IF(AJ8="","",AVERAGE($AD4:AJ8)) -> 0.90484101 | AK9: =IF(AK8="","",AVERAGE($AK4:AK8)) -> 0.98358333 | AL9: =IF(AL8="","",AVERAGE($AK4:AL8)) -> 0.94020833 | AM9: =IF(AM8="","",AVERAGE($AK4:AM8)) -> 0.93163889 | AN9: =IF(AN8="","",AVERAGE($AK4:AN8)) -> 0.92859896 | AO9: =IF(AO8="","",AVERAGE($AK4:AO8)) -> 0.9278125 | AP9: =IF(AP8="","",AVERAGE($AK4:AP8)) -> 0.92429745 | AQ9: =IF(AQ8="","",AVERAGE($AK4:AQ8)) -> 0.9228468 | AR9: =IF(AR8="","",AVERAGE($AR4:AR8)) -> 0.91008333 | AS9: =IF(AS8="","",AVERAGE($AR4:AS8)) -> 0.90688889 | AT9: =IF(AT8="","",AVERAGE($AR4:AT8)) -> 0.90392037 | AU9: =IF(AU8="","",AVERAGE($AR4:AU8)) -> 0.90160884 | AV9: =IF(AV8="","",AVERAGE($AR4:AV8)) -> 0.89931763 | AW9: =IF(AW8="","",AVERAGE($AR4:AW8)) -> 0.89889824 | AX9: =IF(AX8="","",AVERAGE($AR4:AX8)) -> 0.89791532 | AY9: =IF(AY8="","",AVERAGE($AY4:AY8)) -> 0.88337222 | AZ9: =IF(AZ8="","",AVERAGE($AY4:AZ8)) -> 0.88346215 | BA9: =IF(BA8="","",AVERAGE($AY4:BA8)) -> 0.88525418 | BB9: =IF(BB8="","",AVERAGE($AY4:BB8)) -> 0.88368369 | BC9: =IF(BC8="","",AVERAGE($AY4:BC8)) -> 0.88191976 | BD9: =IF(BD8="","",AVERAGE($AY4:BD8)) -> 0.87993522 | BE9: =IF(BE8="","",AVERAGE($AY4:BE8)) -> 0.87924436 | BF9: =IF(BF8="","",AVERAGE($BF4:BF8)) -> 0.87635985 | BG9: =IF(BG8="","",AVERAGE($BF4:BG8)) -> 0.87845529 | BH9: =IF(BH8="","",AVERAGE($BF4:BH8)) -> 0.88026764 | BI9: =IF(BI8="","",AVERAGE($BF4:BI8)) -> 0.88200823 | BJ9: =IF(BJ8="","",AVERAGE($BF4:BJ8)) -> 0.88361043 | BK9: =IF(BK8="","",AVERAGE($BF4:BK8)) -> 0.88516199 | BL9: =IF(BL8="","",AVERAGE($BF4:BL8)) -> 0.88644539 | BM9: =IF(BM8="","",AVERAGE($BM4:BM8)) -> 0.74058333 | BN9: =IF(BN8="","",AVERAGE($BM4:BN8)) -> 0.74583333 | BO9: =IF(BO8="","",AVERAGE($BM4:BO8)) -> 0.73537963 | BP9: =IF(BP8="","",AVERAGE($BM4:BP8)) -> 0.74799826 | BQ9: =IF(BQ8="","",AVERAGE($BM4:BQ8)) -> 0.75590194 | BR9: =IF(BR8="","",AVERAGE($BM4:BR8)) -> 0.76139977 | BS9: =IF(BS8="","",AVERAGE($BM4:BS8)) -> 0.7689481 | BT9: =IF(BT8="","",AVERAGE($BT4:BT8)) -> 0.83121875 | BU9: =IF(BU8="","",AVERAGE($BT4:BU8)) -> 0.83187789 | BV9: =IF(BV8="","",AVERAGE($BT4:BV8)) -> 0.83132415 | BW9: =IF(BW8="","",AVERAGE($BT4:BW8)) -> 0.83373743 | BX9: =IF(BX8="","",AVERAGE($BT4:BX8)) -> 0.837033 | BY9: =IF(BY8="","",AVERAGE($BT4:BY8)) -> 0.83922622 | BZ9: =IF(BZ8="","",AVERAGE($BT4:BZ8)) -> 0.84128404 | CA9: =IF(CA8="","",AVERAGE($CA4:CA8)) -> 0.86198889 | CB9: =IF(CB8="","",AVERAGE($CA4:CB8)) -> 0.86494757 | CC9: =IF(CC8="","",AVERAGE($CA4:CC8)) -> 0.86794707 | CD9: =IF(CD8="","",AVERAGE($CA4:CD8)) -> 0.86970683 | CE9: =IF(CE8="","",AVERAGE($CA4:CE8)) -> 0.8665988 | CF9: =IF(CF8="","",AVERAGE($CA4:CF8)) -> 0.8622983 | CG9: =IF(CG8="","",AVERAGE($CA4:CG8)) -> 0.85986793 | CH9: =IF(CH8="","",AVERAGE($CH4:CH8)) -> 0.85231818 | CI9: =IF(CI8="","",AVERAGE($CH4:CI8)) -> 0.85232938 | CJ9: =IF(CJ8="","",AVERAGE($CH4:CJ8)) -> 0.8543469 | CK9: =IF(CK8="","",AVERAGE($CH4:CK8)) -> 0.85636351 | CL9: =IF(CL8="","",AVERAGE($CH4:CL8)) -> 0.85788504 | CM9: =IF(CM8="","",AVERAGE($CH4:CM8)) -> 0.8592113 | CN9: =IF(CN8="","",AVERAGE($CH4:CN8)) -> 0.8608431 | CO9: =IF(CO8="","",AVERAGE($CO4:CO8)) -> 0.87449713 | CP9: =IF(CP8="","",AVERAGE($CO4:CP8)) -> 0.87264301 | CQ9: =IF(CQ8="","",AVERAGE($CO4:CQ8)) -> 0.87245107 | CR9: =IF(CR8="","",AVERAGE($CO4:CR8)) -> 0.83150497 | CS9: =IF(CS8="","",AVERAGE($CO4:CS8)) -> 0.82702064 | CT9: =IF(CT8="","",AVERAGE($CO4:CT8)) -> 0.82643387 | CU9: =IF(CU8="","",AVERAGE($CO4:CU8)) -> 0.82250284 | CV9: =IF(CV8="","",AVERAGE($CV4:CV8)) -> 0.78716667 | CW9: =IF(CW8="","",AVERAGE($CV4:CW8)) -> 0.79240278 | CX9: =IF(CX8="","",AVERAGE($CV4:CX8)) -> 0.79962963 | CY9: =IF(CY8="","",AVERAGE($CV4:CY8)) -> 0.80868056 | CZ9: =IF(CZ8="","",AVERAGE($CV4:CZ8)) -> 0.81775926 | DA9: =IF(DA8="","",AVERAGE($CV4:DA8)) -> 0.82624383 | DB9: =IF(DB8="","",AVERAGE($CV4:DB8)) -> 0.83217761 | DC9: =IF(DC8="","",AVERAGE($DC4:DC8)) -> 0.87879861 | DD9: =IF(DD8="","",AVERAGE($DC4:DD8)) -> 0.87788649 | DE9: =IF(DE8="","",AVERAGE($DC4:DE8)) -> 0.87964258 | DF9: =IF(DF8="","",AVERAGE($DC4:DF8)) -> 0.88246804 | DG9: =IF(DG8="","",AVERAGE($DC4:DG8)) -> 0.88408798 | DH9: =IF(DH8="","",AVERAGE($DC4:DH8)) -> 0.88528492 | DI9: =IF(DI8="","",AVERAGE($DC4:DI8)) -> 0.88687054 | DJ9: =IF(DJ8="","",AVERAGE($DJ4:DJ8)) -> 0.89514912 | DK9: =IF(DK8="","",AVERAGE($DJ4:DK8)) -> 0.88844956 | DL9: =IF(DL8="","",AVERAGE($DJ4:DL8)) -> 0.88784997 | DM9: =IF(DM8="","",AVERAGE($DJ4:DM8)) -> 0.88824543 | DN9: =IF(DN8="","",AVERAGE($DJ4:DN8)) -> 0.88917678 | DO9: =IF(DO8="","",AVERAGE($DJ4:DO8)) -> 0.89033192 | DP9: =IF(DP8="","",AVERAGE($DJ4:DP8)) -> 0.8917507 | DQ9: =IF(DQ8="","",AVERAGE($DQ4:DQ8)) -> 0.90409936 | DR9: =IF(DR8="","",AVERAGE($DQ4:DR8)) -> 0.90452499 | DS9: =IF(DS8="","",AVERAGE($DQ4:DS8)) -> 0.90499483 | DT9: =IF(DT8="","",AVERAGE($DQ4:DT8)) -> 0.90595949 | DU9: =IF(DU8="","",AVERAGE($DQ4:DU8)) -> 0.90514481 | DV9: =IF(DV8="","",AVERAGE($DQ4:DV8)) -> 0.89820401 | DW9: =IF(DW8="","",AVERAGE($DQ4:DW8)) -> 0.90004391 | DX9: =IF(DX8="","",AVERAGE($DX4:DX8)) -> 0.84086111 | DY9: =IF(DY8="","",AVERAGE($DX4:DY8)) -> 0.85465972 | DZ9: =IF(DZ8="","",AVERAGE($DX4:DZ8)) -> 0.86732315 | EA9: =IF(EA8="","",AVERAGE($DX4:EA8)) -> 0.87324931 | EB9: =IF(EB8="","",AVERAGE($DX4:EB8)) -> 0.87882563 | EC9: =IF(EC8="","",AVERAGE($DX4:EC8)) -> 0.88116025 | ED9: =IF(ED8="","",AVERAGE($DX4:ED8)) -> 0.88452889 | EE9: =IF(EE8="","",AVERAGE($EE4:EE8)) -> 0.90760833 | EF9: =IF(EF8="","",AVERAGE($EE4:EF8)) -> 0.89565644 | EG9: =IF(EG8="","",AVERAGE($EE4:EG8)) -> 0.89163902 | EH9: =IF(EH8="","",AVERAGE($EE4:EH8)) -> 0.88429977 | EI9: =IF(EI8="","",AVERAGE($EE4:EI8)) -> 0.88186363 | EJ9: =IF(EJ8="","",AVERAGE($EE4:EJ8)) -> 0.87796414 | EK9: =IF(EK8="","",AVERAGE($EE4:EK8)) -> 0.87641494 | EL9: =IF(EL8="","",AVERAGE($EL4:EL8)) -> 0.86077941 | EM9: =IF(EM8="","",AVERAGE($EL4:EM8)) -> 0.86153091 | EN9: =IF(EN8="","",AVERAGE($EL4:EN8)) -> 0.86304254 | EO9: =IF(EO8="","",AVERAGE($EL4:EO8)) -> 0.86285274 | EP9: =IF(EP8="","",AVERAGE($EL4:EP8)) -> 0.86321155 | EQ9: =IF(EQ8="","",AVERAGE($EL4:EQ8)) -> 0.86434359 | ER9: =IF(ER8="","",AVERAGE($EL4:ER8)) -> 0.86451397 | ES9: =IF(ES8="","",AVERAGE($ES4:ES8)) -> 0.85903125 | ET9: =IF(ET8="","",AVERAGE($ES4:ET8)) -> 0.86128729 | EU9: =IF(EU8="","",AVERAGE($ES4:EU8)) -> 0.86278448 | EV9: =IF(EV8="","",AVERAGE($ES4:EV8)) -> 0.86417786 | EW9: =IF(EW8="","",AVERAGE($ES4:EW8)) -> 0.86556551 | EX9: =IF(EX8="","",AVERAGE($ES4:EX8)) -> 0.86723131 | EY9: =IF(EY8="","",AVERAGE($ES4:EY8)) -> 0.86901374 | EZ9: =IF(EZ8="","",AVERAGE($EZ4:EZ8)) -> 0.88358871 | FA9: =IF(FA8="","",AVERAGE($EZ4:FA8)) -> 0.94179435 | FB9: =IF(FB8="","",AVERAGE($EZ4:FB8)) -> 0.96119624 | FC9: =IF(FC8="","",AVERAGE($EZ4:FC8)) -> 0.97089718 | FD9: =IF(FD8="","",AVERAGE($EZ4:FD8)) -> 0.97671774 | FE9: =IF(FE8="","",AVERAGE($EZ4:FE8)) -> 0.98059812 | FF9: =IF(FF8="","",AVERAGE($EZ4:FF8)) -> 0.98336982 | FG9: =IF(FG8="","",AVERAGE($FG4:FG8)) -> 0.99458333 | FH9: =IF(FH8="","",AVERAGE($FG4:FH8)) -> 0.98079167 | FI9: =IF(FI8="","",AVERAGE($FG4:FI8)) -> 0.97387037 | FJ9: =IF(FJ8="","",AVERAGE($FG4:FJ8)) -> 0.96627778 | FK9: =IF(FK8="","",AVERAGE($FG4:FK8)) -> 0.96099949 | FL9: =IF(FL8="","",AVERAGE($FG4:FL8)) -> 0.95568592 | FM9: =IF(FM8="","",AVERAGE($FG4:FM8)) -> 0.95203024 | FN9: =IF(FN8="","",AVERAGE($FN4:FN8)) -> 0.9215 | FO9: =IF(FO8="","",AVERAGE(FN4:FO8)) -> 0.92322778 | FP9: =IF(FP8="","",AVERAGE(FN4:FP8)) -> 0.92447824 | FQ9: =IF(FQ8="","",AVERAGE(FN4:FQ8)) -> 0.92617731 | FR9: =IF(FR8="","",AVERAGE(FN4:FR8)) -> 0.92502888 | FS9: =IF(FS8="","",AVERAGE(FN4:FS8)) -> 0.92025068 | FT9: =IF(FT8="","",AVERAGE(FN4:FT8)) -> 0.91702856 | FU9: =IF(FU8="","",AVERAGE($FN4:FU8)) -> 0.90758104 | FV9: =IF(FV8="","",AVERAGE(FU4:FV8)) -> 0.84231133 | FW9: =IF(FW8="","",AVERAGE(FU4:FW8)) -> 0.8416375 | FX9: =IF(FX8="","",AVERAGE(FU4:FX8)) -> 0.84107014 | FY9: =IF(FY8="","",AVERAGE(FU4:FY8)) -> 0.84060745 | FZ9: =IF(FZ8="","",AVERAGE(FU4:FZ8)) -> 0.840253 | GA9: =IF(GA8="","",AVERAGE(FU4:GA8)) -> 0.84003829 | GB9: =IF(GB8="","",AVERAGE($FN4:GB8)) -> 0.87076195 | GC9: =IF(GC8="","",AVERAGE(GB4:GC8)) -> 0.76441025 | GD9: =IF(GD8="","",AVERAGE(GB4:GD8)) -> 0.76769665 | GE9: =IF(GE8="","",AVERAGE(GB4:GE8)) -> 0.69212665 | GF9: =IF(GF8="","",AVERAGE(GB4:GF8)) -> 0.68785132 | GG9: =IF(GG8="","",AVERAGE(GB4:GG8)) -> 0.69206592 | GH9: =IF(GH8="","",AVERAGE(GB4:GH8)) -> 0.69472614 | GI9: =IF(GI8="","",AVERAGE($FN4:GI8)) -> 0.81431898 | GJ9: =IF(GJ8="","",AVERAGE(GI4:GJ8)) -> 0.70976111 | GK9: =IF(GK8="","",AVERAGE(GI4:GK8)) -> 0.70205503 | GL9: =IF(GL8="","",AVERAGE(GI4:GL8)) -> 0.70632252 | GM9: =IF(GM8="","",AVERAGE(GI4:GM8)) -> 0.71394135 | GN9: =IF(GN8="","",AVERAGE(GI4:GN8)) -> 0.72328029 | GO9: =IF(GO8="","",AVERAGE(GI4:GO8)) -> 0.71228029 | GP9: =IF(GP8="","",AVERAGE($FN4:GP8)) -> 0.78673464 | GQ9: =IF(GQ8="","",AVERAGE(GP4:GQ8)) -> 0.67960737 | GR9: =IF(GR8="","",AVERAGE(GP4:GR8)) -> 0.69120253 | GS9: =IF(GS8="","",AVERAGE(GP4:GS8)) -> 0.70176023 | GT9: =IF(GT8="","",AVERAGE(GP4:GT8)) -> 0.71142694 | GU9: =IF(GU8="","",AVERAGE(GP4:GU8)) -> 0.71640643 | GV9: =IF(GV8="","",AVERAGE(GP4:GV8)) -> 0.72201636 | GW9: =IF(GW8="","",AVERAGE($FN4:GW8)) -> 0.77683566 | GX9: =IF(GX8="","",AVERAGE(GW4:GX8)) -> 0.75940724 | GY9: =IF(GY8="","",AVERAGE(GW4:GY8)) -> 0.7619408 | GZ9: =IF(GZ8="","",AVERAGE(GW4:GZ8)) -> 0.76172833 | HA9: =IF(HA8="","",AVERAGE(GW4:HA8)) -> 0.76367832 | HB9: =IF(HB8="","",AVERAGE(GW4:HB8)) -> 0.76656526 | HC9: =IF(HC8="","",AVERAGE(GW4:HC8)) -> 0.7698788 | HD9: =IF(HD8="","",AVERAGE($FN4:HD8)) -> 0.77650291 | HE9: =IF(HE8="","",AVERAGE(HD4:HE8)) -> 0.80117771 | HF9: =IF(HF8="","",AVERAGE(HD4:HF8)) -> 0.80263633 | HG9: =IF(HG8="","",AVERAGE(HD4:HG8)) -> 0.80377179 | HH9: =IF(HH8="","",AVERAGE(HD4:HH8)) -> 0.80573854 | HI9: =IF(HI8="","",AVERAGE(HD4:HI8)) -> 0.80736635 | HJ9: =IF(HJ8="","",AVERAGE(HD4:HJ8)) -> 0.8144615 | HK9: =IF(HK8="","",AVERAGE($FN4:HK8)) -> 0.78397227 | HL9: =IF(HL8="","",AVERAGE(HK4:HL8)) -> 0.88313696 | HM9: =IF(HM8="","",AVERAGE(HK4:HM8)) -> 0.88159787 | HN9: =IF(HN8="","",AVERAGE(HK4:HN8)) -> 0.87833104 | HO9: =IF(HO8="","",AVERAGE(HK4:HO8)) -> 0.87496105 | HP9: =IF(HP8="","",AVERAGE(HK4:HP8)) -> 0.87062131 | HQ9: =IF(HQ8="","",AVERAGE(HK4:HQ8)) -> 0.86796761 | HR9: =IF(HR8="","",AVERAGE($FN4:HR8)) -> 0.79363035 | HS9: =IF(HS8="","",AVERAGE(HR4:HS8)) -> 0.85994742 | HT9: =IF(HT8="","",AVERAGE(HR4:HT8)) -> 0.86124419 | HU9: =IF(HU8="","",AVERAGE(HR4:HU8)) -> 0.86079503 | HV9: =IF(HV8="","",AVERAGE(HR4:HV8)) -> 0.86059151 | HW9: =IF(HW8="","",AVERAGE(HR4:HW8)) -> 0.86132408 | HX9: =IF(HX8="","",AVERAGE(HR4:HX8)) -> 0.86219571 | HY9: =IF(HY8="","",AVERAGE($FN4:HY8)) -> 0.80122851 | HZ9: =IF(HZ8="","",AVERAGE(HY4:HZ8)) -> 0.8752875 | IA9: =IF(IA8="","",AVERAGE(HY4:IA8)) -> 0.87477243 | IB9: =IF(IB8="","",AVERAGE(HY4:IB8)) -> 0.87454661 | IC9: =IF(IC8="","",AVERAGE(HY4:IC8)) -> 0.87098854 | ID9: =IF(ID8="","",AVERAGE(HY4:ID8)) -> 0.86916207 | IE9: =IF(IE8="","",AVERAGE(HY4:IE8)) -> 0.86842742 | IF9: =IF(IF8="","",AVERAGE($FN4:IF8)) -> 0.80767427 | IG9: =IF(IG8="","",AVERAGE(IF4:IG8)) -> 0.86372053 | IH9: =IF(IH8="","",AVERAGE(IF4:IH8)) -> 0.86478384 | II9: =IF(II8="","",AVERAGE(IF4:II8)) -> 0.86580434 | IJ9: =IF(IJ8="","",AVERAGE(IF4:IJ8)) -> 0.86696639 | IK9: =IF(IK8="","",AVERAGE(IF4:IK8)) -> 0.86402613 | IL9: =IF(IL8="","",AVERAGE(IF4:IL8)) -> 0.86266819 | IM9: =IF(IM8="","",AVERAGE($FN4:IM8)) -> 0.8123255 | IN9: =IF(IN8="","",AVERAGE(IM4:IN8)) -> 0.84023969 | IO9: =IF(IO8="","",AVERAGE(IM4:IO8)) -> 0.86816597 | IP9: =IF(IP8="","",AVERAGE(IM4:IP8)) -> 0.8800423 | IQ9: =IF(IQ8="","",AVERAGE(IM4:IQ8)) -> 0.87601362 | IR9: =IF(IR8="","",AVERAGE(IM4:IR8)) -> 0.87346631 | IS9: =IF(IS8="","",AVERAGE(IM4:IS8)) -> 0.87307933 | IT9: =IF(IT8="","",AVERAGE($FN4:IT8)) -> 0.8177728 | IU9: =IF(IU8="","",AVERAGE(IT4:IU8)) -> 0.87863726 | IV9: =IF(IV8="","",AVERAGE(IT4:IV8)) -> 0.88211707 | IW9: =IF(IW8="","",AVERAGE(IT4:IW8)) -> 0.88233343 | IX9: =IF(IX8="","",AVERAGE(IT4:IX8)) -> 0.87779952 | IY9: =IF(IY8="","",AVERAGE(IT4:IY8)) -> 0.87268314 | IZ9: =IF(IZ8="","",AVERAGE(IT4:IZ8)) -> 0.86745685 | JA9: =IF(JA8="","",AVERAGE($FN4:JA8)) -> 0.82086317 | JB9: =IF(JB8="","",AVERAGE(JA4:JB8)) -> 0.80773117 | JC9: =IF(JC8="","",AVERAGE(JA4:JC8)) -> 0.80682438 | JD9: =IF(JD8="","",AVERAGE(JA4:JD8)) -> 0.80693686 | JE9: =IF(JE8="","",AVERAGE(JA4:JE8)) -> 0.80915314 | JF9: =IF(JF8="","",AVERAGE(JA4:JF8)) -> 0.81224053 | JG9: =IF(JG8="","",AVERAGE(JA4:JG8)) -> 0.81512926 | JH9: =IF(JH8="","",AVERAGE($FN4:JH8)) -> 0.82072005 | JI9: =IF(JI8="","",AVERAGE(JH4:JI8)) -> 0.84361948 | JJ9: =IF(JJ8="","",AVERAGE(JH4:JJ8)) -> 0.84720248 | JK9: =IF(JK8="","",AVERAGE(JH4:JK8)) -> 0.84967858 | JL9: =IF(JL8="","",AVERAGE(JH4:JL8)) -> 0.85048471 | JM9: =IF(JM8="","",AVERAGE(JH4:JM8)) -> 0.85037335 | JN9: =IF(JN8="","",AVERAGE(JH4:JN8)) -> 0.85069129 | JO9: =IF(JO8="","",AVERAGE($FN4:JO8)) -> 0.82285305 | JP9: =IF(JP8="","",AVERAGE(JO4:JP8)) -> 0.85756999 | JQ9: =IF(JQ8="","",AVERAGE(JO4:JQ8)) -> 0.85788611 | JR9: =IF(JR8="","",AVERAGE(JO4:JR8)) -> 0.85887597 | JS9: =IF(JS8="","",AVERAGE(JO4:JS8)) -> 0.86301327 | JT9: =IF(JT8="","",AVERAGE(JO4:JT8)) -> 0.86665516 | JU9: =IF(JU8="","",AVERAGE(JO4:JU8)) -> 0.84944516 | JV9: =IF(JV8="","",AVERAGE($FN4:JV8)) -> 0.82393511 | JW9: =IF(JW8="","",AVERAGE(JV4:JW8)) -> 0.81110885 | JX9: =IF(JX8="","",AVERAGE(JV4:JX8)) -> 0.82478155 | JY9: =IF(JY8="","",AVERAGE(JV4:JY8)) -> 0.83621455 | JZ9: =IF(JZ8="","",AVERAGE(JV4:JZ8)) -> 0.84631151 | KA9: =IF(KA8="","",AVERAGE(JV4:KA8)) -> 0.8545237 | KB9: =IF(KB8="","",AVERAGE(JV4:KB8)) -> 0.85902405 | KC9: =IF(KC8="","",AVERAGE($FN4:KC8)) -> 0.82669841 | KD9: =IF(KD8="","",AVERAGE(KC4:KD8)) -> 0.88328036 | KE9: =IF(KE8="","",AVERAGE(KC4:KE8)) -> 0.88783464 | KF9: =IF(KF8="","",AVERAGE(KC4:KF8)) -> 0.88838065 | KG9: =IF(KG8="","",AVERAGE(KC4:KG8)) -> 0.88950801 | KH9: =IF(KH8="","",AVERAGE(KC4:KH8)) -> 0.89136357 | KI9: =IF(KI8="","",AVERAGE(KC4:KI8)) -> 0.89352391 | KJ9: =IF(KJ8="","",AVERAGE($FN4:KJ8)) -> 0.83064529 | KK9: =IF(KK8="","",AVERAGE(KJ4:KK8)) -> 0.90611064 | KL9: =IF(KL8="","",AVERAGE(KJ4:KL8)) -> 0.90591145 | KM9: =IF(KM8="","",AVERAGE(KJ4:KM8)) -> 0.90634147 | KN9: =IF(KN8="","",AVERAGE(KJ4:KN8)) -> 0.90743919 | KO9: =IF(KO8="","",AVERAGE(KJ4:KO8)) -> 0.90880991 | KP9: =IF(KP8="","",AVERAGE(KJ4:KP8)) -> 0.91029101 | KQ9: =IF(KQ8="","",AVERAGE($FN4:KQ8)) -> 0.83488596 | KR9: =IF(KR8="","",AVERAGE(KQ4:KR8)) -> 0.92390257 | KS9: =IF(KS8="","",AVERAGE(KQ4:KS8)) -> 0.92532099 | KT9: =IF(KT8="","",AVERAGE(KQ4:KT8)) -> 0.92667165 | KU9: =IF(KU8="","",AVERAGE(KQ4:KU8)) -> 0.92795981 | KV9: =IF(KV8="","",AVERAGE(KQ4:KV8)) -> 0.92919019 | KW9: =IF(KW8="","",AVERAGE(KQ4:KW8)) -> 0.93036699 | KX9: =IF(KX8="","",AVERAGE($FN4:KX8)) | KY9: =IF(KY8="","",AVERAGE(KX4:KY8)) | KZ9: =IF(KZ8="","",AVERAGE(KX4:KZ8)) | LA9: =IF(LA8="","",AVERAGE(KX4:LA8)) | LB9: =IF(LB8="","",AVERAGE(KX4:LB8)) | LC9: =IF(LC8="","",AVERAGE(KX4:LC8)) | LD9: =IF(LD8="","",AVERAGE(KX4:LD8)) | LE9: =IF(LE8="","",AVERAGE($FN4:LE8)) | LF9: =IF(LF8="","",AVERAGE(LE4:LF8)) | LG9: =IF(LG8="","",AVERAGE(LE4:LG8)) | LH9: =IF(LH8="","",AVERAGE(LE4:LH8)) | LI9: =IF(LI8="","",AVERAGE(LE4:LI8)) | LJ9: =IF(LJ8="","",AVERAGE(LE4:LJ8)) | LK9: =IF(LK8="","",AVERAGE(LE4:LK8)) | LL9: =IF(LL8="","",AVERAGE($FN4:LL8)) | LM9: =IF(LM8="","",AVERAGE(LL4:LM8)) | LN9: =IF(LN8="","",AVERAGE(LL4:LN8)) | LO9: =IF(LO8="","",AVERAGE(LL4:LO8)) | LP9: =IF(LP8="","",AVERAGE(LL4:LP8)) | LQ9: =IF(LQ8="","",AVERAGE(LL4:LQ8)) | LR9: =IF(LR8="","",AVERAGE(LL4:LR8)) | LS9: =IF(LS8="","",AVERAGE($FN4:LS8)) | LT9: =IF(LT8="","",AVERAGE(LS4:LT8)) | LU9: =IF(LU8="","",AVERAGE(LS4:LU8)) | LV9: =IF(LV8="","",AVERAGE(LS4:LV8)) | LW9: =IF(LW8="","",AVERAGE(LS4:LW8)) | LX9: =IF(LX8="","",AVERAGE(LS4:LX8)) | LY9: =IF(LY8="","",AVERAGE(LS4:LY8)) | LZ9: =IF(LZ8="","",AVERAGE($FN4:LZ8)) | MA9: =IF(MA8="","",AVERAGE(LZ4:MA8)) | MB9: =IF(MB8="","",AVERAGE(LZ4:MB8)) | MC9: =IF(MC8="","",AVERAGE(LZ4:MC8)) | MD9: =IF(MD8="","",AVERAGE(LZ4:MD8)) | ME9: =IF(ME8="","",AVERAGE(LZ4:ME8)) | MF9: =IF(MF8="","",AVERAGE(LZ4:MF8)) | MG9: =IF(MG8="","",AVERAGE($FN4:MG8)) | MH9: =IF(MH8="","",AVERAGE(MG4:MH8)) | MI9: =IF(MI8="","",AVERAGE(MG4:MI8)) | MJ9: =IF(MJ8="","",AVERAGE(MG4:MJ8)) | MK9: =IF(MK8="","",AVERAGE(MG4:MK8)) | ML9: =IF(ML8="","",AVERAGE(MG4:ML8)) | MM9: =IF(MM8="","",AVERAGE(MG4:MM8)) | MN9: =IF(MN8="","",AVERAGE($FN4:MN8)) | MO9: =IF(MO8="","",AVERAGE(MN4:MO8)) | MP9: =IF(MP8="","",AVERAGE(MN4:MP8)) | MQ9: =IF(MQ8="","",AVERAGE(MN4:MQ8)) | MR9: =IF(MR8="","",AVERAGE(MN4:MR8)) | MS9: =IF(MS8="","",AVERAGE(MN4:MS8)) | MT9: =IF(MT8="","",AVERAGE(MN4:MT8)) | MU9: =IF(MU8="","",AVERAGE($FN4:MU8)) | MV9: =IF(MV8="","",AVERAGE(MU4:MV8)) | MW9: =IF(MW8="","",AVERAGE(MU4:MW8)) | MX9: =IF(MX8="","",AVERAGE(MU4:MX8)) | MY9: =IF(MY8="","",AVERAGE(MU4:MY8)) | MZ9: =IF(MZ8="","",AVERAGE(MU4:MZ8)) | NA9: =IF(NA8="","",AVERAGE(MU4:NA8)) | NB9: =IF(NB8="","",AVERAGE($FN4:NB8)) | NC9: =IF(NC8="","",AVERAGE(NB4:NC8)) | ND9: =IF(ND8="","",AVERAGE(NB4:ND8)) | NE9: =IF(NE8="","",AVERAGE(NB4:NE8)) | NF9: =IF(NF8="","",AVERAGE(NB4:NF8)) | NG9: =IF(NG8="","",AVERAGE(NB4:NG8)) | NH9: =IF(NH8="","",AVERAGE(NB4:NH8)) | NI9: =IF(NI8="","",AVERAGE($FN4:NI8)) | NJ9: =IF(NJ8="","",AVERAGE(NI4:NJ8)) | NK9: =IF(NK8="","",AVERAGE(NI4:NK8)) | NL9: =IF(NL8="","",AVERAGE(NI4:NL8)) | NM9: =IF(NM8="","",AVERAGE(NI4:NM8)) | NN9: =IF(NN8="","",AVERAGE(NI4:NN8)) | NO9: =IF(NO8="","",AVERAGE(NI4:NO8)) | NP9: =IF(NP8="","",AVERAGE($FN4:NP8)) | NQ9: =IF(NQ8="","",AVERAGE(NP4:NQ8)) | NR9: =IF(NR8="","",AVERAGE(NP4:NR8)) | NS9: =IF(NS8="","",AVERAGE(NP4:NS8)) | NT9: =IF(NT8="","",AVERAGE(NP4:NT8)) | NU9: =IF(NU8="","",AVERAGE(NP4:NU8)) | NV9: =IF(NV8="","",AVERAGE(NP4:NV8)) | NW9: =IF(NW8="","",AVERAGE($FN4:NW8)) | NX9: =IF(NX8="","",AVERAGE(NW4:NX8)) | NY9: =IF(NY8="","",AVERAGE(NW4:NY8)) | NZ9: =IF(NZ8="","",AVERAGE(NW4:NZ8)) | OA9: =IF(OA8="","",AVERAGE(NW4:OA8)) | OB9: =IF(OB8="","",AVERAGE(NW4:OB8)) | OC9: =IF(OC8="","",AVERAGE(NW4:OC8)) | OD9: =IF(OD8="","",AVERAGE($FN4:OD8)) | OE9: =IF(OE8="","",AVERAGE(OD4:OE8)) | OF9: =IF(OF8="","",AVERAGE(OD4:OF8)) | OG9: =IF(OG8="","",AVERAGE(OD4:OG8)) | OH9: =IF(OH8="","",AVERAGE(OD4:OH8)) | OI9: =IF(OI8="","",AVERAGE(OD4:OI8)) | OJ9: =IF(OJ8="","",AVERAGE(OD4:OJ8)) | OK9: =IF(OK8="","",AVERAGE($FN4:OK8)) | OL9: =IF(OL8="","",AVERAGE(OK4:OL8)) | OM9: =IF(OM8="","",AVERAGE(OK4:OM8)) | ON9: =IF(ON8="","",AVERAGE(OK4:ON8)) | OO9: =IF(OO8="","",AVERAGE(OK4:OO8)) | OP9: =IF(OP8="","",AVERAGE(OK4:OP8)) | OQ9: =IF(OQ8="","",AVERAGE(OK4:OQ8)) | OR9: =IF(OR8="","",AVERAGE($FN4:OR8)) | OS9: =IF(OS8="","",AVERAGE(OR4:OS8)) | OT9: =IF(OT8="","",AVERAGE(OR4:OT8)) | OU9: =IF(OU8="","",AVERAGE(OR4:OU8)) | OV9: =IF(OV8="","",AVERAGE(OR4:OV8)) | OW9: =IF(OW8="","",AVERAGE(OR4:OW8)) | OX9: =IF(OX8="","",AVERAGE(OR4:OX8)) | OY9: =IF(OY8="","",AVERAGE($OY4:OY8)) | OZ9: =IF(OZ8="","",AVERAGE($OY4:OZ8))
A10: =ISODD(B10) -> TRUE | B10: 7 | C10: =C9 -> Mechanical Availability | D10: =D9 -> 777E Expro | E10: Overall MTD | F10: =IF('All Fleet'!B49="","",'All Fleet'!C49) -> 1 | G10: =IF('All Fleet'!C49="","",'All Fleet'!D49) -> 1 | H10: =IF('All Fleet'!D49="","",'All Fleet'!E49) -> 0.99333333 | I10: =IF('All Fleet'!E49="","",'All Fleet'!F49) -> 0.995 | J10: =IF('All Fleet'!F49="","",'All Fleet'!G49) -> 0.996 | K10: =IF('All Fleet'!G49="","",'All Fleet'!H49) -> 0.98663889 | L10: =IF('All Fleet'!H49="","",'All Fleet'!I49) -> 0.98679762 | M10: =IF('All Fleet'!I49="","",'All Fleet'!J49) -> 0.96084375 | ... OZ10: =IF('All Fleet'!OV49="","",'All Fleet'!OW49)
A11: =ISODD(B11) -> FALSE | B11: 8 | C11: =C10 -> Mechanical Availability | D11: =D10 -> 777E Expro | E11: Overall YTD | F11: =IF('All Fleet'!C62="","",'All Fleet'!C62) -> 1 | G11: =IF('All Fleet'!D62="","",'All Fleet'!D62) -> 1 | H11: =IF('All Fleet'!E62="","",'All Fleet'!E62) -> 0.99333333 | I11: =IF('All Fleet'!F62="","",'All Fleet'!F62) -> 0.995 | J11: =IF('All Fleet'!G62="","",'All Fleet'!G62) -> 0.996 | K11: =IF('All Fleet'!H62="","",'All Fleet'!H62) -> 0.98663889 | L11: =IF('All Fleet'!I62="","",'All Fleet'!I62) -> 0.98679762 | M11: =IF('All Fleet'!J62="","",'All Fleet'!J62) -> 0.96084375 | ... OZ11: =IF('All Fleet'!OW62="","",'All Fleet'!OW62)
A12: =ISODD(B12) -> TRUE | B12: 9 | C12: =C11 -> Mechanical Availability | D12: =D11 -> 777E Expro | E12: Quota Monthly (hrs) | F12: =IF('All Fleet'!C75="","",((COUNTIFS('All Fleet'!$A$66:$A$74,"777E")*'All Fleet'!C$5)*11.8%)-'All Fleet'!C75) -> 14.16 | G12: =IF('All Fleet'!D75="","",((COUNTIFS('All Fleet'!$A$66:$A$74,"777E")*'All Fleet'!D$5)*11.8%)-'All Fleet'!D75) -> 28.32 | H12: =IF('All Fleet'!E75="","",((COUNTIFS('All Fleet'!$A$66:$A$74,"777E")*'All Fleet'!E$5)*11.8%)-'All Fleet'!E75) -> 40.08 | I12: =IF('All Fleet'!F75="","",((COUNTIFS('All Fleet'!$A$66:$A$74,"777E")*'All Fleet'!F$5)*11.8%)-'All Fleet'!F75) -> 54.24 | J12: =IF('All Fleet'!G75="","",((COUNTIFS('All Fleet'!$A$66:$A$74,"777E")*'All Fleet'!G$5)*11.8%)-'All Fleet'!G75) -> 68.4 | K12: =IF('All Fleet'!H75="","",((COUNTIFS('All Fleet'!$A$66:$A$74,"777E")*'All Fleet'!H$5)*11.8%)-'All Fleet'!H75) -> 75.34 | L12: =IF('All Fleet'!I75="","",((COUNTIFS('All Fleet'!$A$66:$A$74,"777E")*'All Fleet'!I$5)*11.8%)-'All Fleet'!I75) -> 88.03 | M12: =IF('All Fleet'!J75="","",((COUNTIFS('All Fleet'!$A$66:$A$74,"777E")*'All Fleet'!J$5)*11.8%)-'All Fleet'!J75) -> 75.69 | ... OZ12: =IF('All Fleet'!OW75="","",((COUNTIFS('All Fleet'!$A$66:$A$74,"777E")*'All Fleet'!OW$5)*11.8%)-'All Fleet'!OW75)
A13: =ISODD(B13) -> FALSE | B13: 10 | C13: =C12 -> Mechanical Availability | D13: =D12 -> 777E Expro | E13: Quota Daily (hrs) | F13: =IF('All Fleet'!C75="","",(4*24*11.8%)-'All Fleet'!C22) -> 11.328 | G13: =IF('All Fleet'!D75="","",(4*24*11.8%)-'All Fleet'!D22) -> 11.328 | H13: =IF('All Fleet'!E75="","",(4*24*11.8%)-'All Fleet'!E22) -> 8.928 | I13: =IF('All Fleet'!F75="","",(4*24*11.8%)-'All Fleet'!F22) -> 11.328 | J13: =IF('All Fleet'!G75="","",(4*24*11.8%)-'All Fleet'!G22) -> 11.328 | K13: =IF('All Fleet'!H75="","",(4*24*11.8%)-'All Fleet'!H22) -> 4.108 | L13: =IF('All Fleet'!I75="","",(4*24*11.8%)-'All Fleet'!I22) -> 9.858 | M13: =IF('All Fleet'!J75="","",(4*24*11.8%)-'All Fleet'!J22) -> -15.172 | ... AJ13: =IF('All Fleet'!AG75="","",(4*24*11.8%)-'All Fleet'!AG22) -> 5.348 | AK13: =IF('All Fleet'!AH75="","",(5*24*11.8%)-'All Fleet'!AH22) -> 12.19 | AL13: =IF('All Fleet'!AI75="","",(5*24*11.8%)-'All Fleet'!AI22) -> -8.63 | AM13: =IF('All Fleet'!AJ75="","",(5*24*11.8%)-'All Fleet'!AJ22) -> 8.14 | AN13: =IF('All Fleet'!AK75="","",(5*24*11.8%)-'All Fleet'!AK22) -> 6.29 | AO13: =IF('All Fleet'!AL75="","",(5*24*11.8%)-'All Fleet'!AL22) -> 7.61 | AP13: =IF('All Fleet'!AM75="","",(5*24*11.8%)-'All Fleet'!AM22) -> -7.8 | AQ13: =IF('All Fleet'!AN75="","",(5*24*11.8%)-'All Fleet'!AN22) -> 9.2 | AR13: =IF('All Fleet'!AO75="","",(5*24*11.8%)-'All Fleet'!AO22) -> -0.04 | ... OZ13: =IF('All Fleet'!OW75="","",(5*24*11.8%)-'All Fleet'!OW22)
A14: =ISODD(B14) -> TRUE | B14: 11 | C14: =C13 -> Mechanical Availability | D14: 777 Optiload | E14: RT406 | F14: =IF('All Fleet'!C58="","",'All Fleet'!C58) -> 1 | G14: =IF('All Fleet'!D58="","",'All Fleet'!D58) -> -0.1275 | H14: =IF('All Fleet'!E58="","",'All Fleet'!E58) -> 0.24833333 | I14: =IF('All Fleet'!F58="","",'All Fleet'!F58) -> 0.43625 | J14: =IF('All Fleet'!G58="","",'All Fleet'!G58) -> 0.293 | K14: =IF('All Fleet'!H58="","",'All Fleet'!H58) -> 0.36118056 | L14: =IF('All Fleet'!I58="","",'All Fleet'!I58) -> 0.45244048 | M14: =IF('All Fleet'!J58="","",'All Fleet'!J58) -> 0.45989583 | ... EZ14: =IF('All Fleet'!EW58="","",'All Fleet'!EW58) -> 0.88234823 | FA14: ='All Fleet'!EX45 -> 1 | FB14: ='All Fleet'!EY45 -> 1 | FC14: ='All Fleet'!EZ45 -> 1 | FD14: ='All Fleet'!FA45 -> 1 | FE14: ='All Fleet'!FB45 -> 1 | FF14: ='All Fleet'!FC45 -> 1 | FG14: ='All Fleet'!FD45 -> 0.97547619 | FH14: ='All Fleet'!FE45 -> 0.97854167 | ... OZ14: ='All Fleet'!OW45
A15: =ISODD(B15) -> FALSE | B15: 12 | C15: =C14 -> Mechanical Availability | D15: =D14 -> 777 Optiload | E15: RT407 | F15: =IF('All Fleet'!C59="","",'All Fleet'!C59) -> 1 | G15: =IF('All Fleet'!D59="","",'All Fleet'!D59) -> 1 | H15: =IF('All Fleet'!E59="","",'All Fleet'!E59) -> 1 | I15: =IF('All Fleet'!F59="","",'All Fleet'!F59) -> 1 | J15: =IF('All Fleet'!G59="","",'All Fleet'!G59) -> 1 | K15: =IF('All Fleet'!H59="","",'All Fleet'!H59) -> 1 | L15: =IF('All Fleet'!I59="","",'All Fleet'!I59) -> 1 | M15: =IF('All Fleet'!J59="","",'All Fleet'!J59) -> 1 | ... EZ15: =IF('All Fleet'!EW59="","",'All Fleet'!EW59) -> 0.87441777 | FA15: ='All Fleet'!EX46 -> 1 | FB15: ='All Fleet'!EY46 -> 1 | FC15: ='All Fleet'!EZ46 -> 1 | FD15: ='All Fleet'!FA46 -> 1 | FE15: ='All Fleet'!FB46 -> 1 | FF15: ='All Fleet'!FC46 -> 1 | FG15: ='All Fleet'!FD46 -> 0.95702381 | FH15: ='All Fleet'!FE46 -> 0.9009375 | ... OZ15: ='All Fleet'!OW46
A16: =ISODD(B16) -> TRUE | B16: 13 | C16: =C15 -> Mechanical Availability | D16: =D15 -> 777 Optiload | E16: RT408 | F16: =IF('All Fleet'!C60="","",'All Fleet'!C60) -> 1 | G16: =IF('All Fleet'!D60="","",'All Fleet'!D60) -> 1 | H16: =IF('All Fleet'!E60="","",'All Fleet'!E60) -> 0.94375 | I16: =IF('All Fleet'!F60="","",'All Fleet'!F60) -> 0.9578125 | J16: =IF('All Fleet'!G60="","",'All Fleet'!G60) -> 0.96625 | K16: =IF('All Fleet'!H60="","",'All Fleet'!H60) -> 0.94256944 | L16: =IF('All Fleet'!I60="","",'All Fleet'!I60) -> 0.89232143 | M16: =IF('All Fleet'!J60="","",'All Fleet'!J60) -> 0.81125 | ... EZ16: =IF('All Fleet'!EW60="","",'All Fleet'!EW60) -> 0.86910872 | FA16: ='All Fleet'!EX47 -> 1 | FB16: ='All Fleet'!EY47 -> 1 | FC16: ='All Fleet'!EZ47 -> 1 | FD16: ='All Fleet'!FA47 -> 1 | FE16: ='All Fleet'!FB47 -> 1 | FF16: ='All Fleet'!FC47 -> 1 | FG16: ='All Fleet'!FD47 -> 0.94595238 | FH16: ='All Fleet'!FE47 -> 0.87640625 | ... OZ16: ='All Fleet'!OW47
A17: =ISODD(B17) -> FALSE | B17: 14 | C17: =C16 -> Mechanical Availability | D17: =D16 -> 777 Optiload | E17: RT409 | F17: =IF('All Fleet'!C61="","",'All Fleet'!C61) -> 1 | G17: =IF('All Fleet'!D61="","",'All Fleet'!D61) -> 1 | H17: =IF('All Fleet'!E61="","",'All Fleet'!E61) -> 1 | I17: =IF('All Fleet'!F61="","",'All Fleet'!F61) -> 1 | J17: =IF('All Fleet'!G61="","",'All Fleet'!G61) -> 1 | K17: =IF('All Fleet'!H61="","",'All Fleet'!H61) -> 1 | L17: =IF('All Fleet'!I61="","",'All Fleet'!I61) -> 1 | M17: =IF('All Fleet'!J61="","",'All Fleet'!J61) -> 1 | ... EZ17: =IF('All Fleet'!EW61="","",'All Fleet'!EW61) -> 0.94168598 | FA17: ='All Fleet'!EX48 -> 1 | FB17: ='All Fleet'!EY48 -> 1 | FC17: ='All Fleet'!EZ48 -> 1 | FD17: ='All Fleet'!FA48 -> 1 | FE17: ='All Fleet'!FB48 -> 1 | FF17: ='All Fleet'!FC48 -> 1 | FG17: ='All Fleet'!FD48 -> 0.95345238 | FH17: ='All Fleet'!FE48 -> 0.9290625 | ... OZ17: ='All Fleet'!OW48
A18: =ISODD(B18) -> TRUE | B18: 15 | E18: Overall Weekly | F18: =IF(F17="","",AVERAGE($F$14:$H$17)) -> 0.83871528 | G18: =IF(G17="","",AVERAGE($F$14:$H$17)) -> 0.83871528 | H18: =IF(H17="","",AVERAGE($F$14:$H$17)) -> 0.83871528 | I18: =IF(I17="","",AVERAGE($I14:I17)) -> 0.84851562 | J18: =IF(J17="","",AVERAGE($I14:J17)) -> 0.83166406 | K18: =IF(K17="","",AVERAGE($I14:K17)) -> 0.82975521 | L18: =IF(L17="","",AVERAGE($I14:L17)) -> 0.83136403 | M18: =IF(M17="","",AVERAGE($I14:M17)) -> 0.82864851 | N18: =IF(N17="","",AVERAGE($I14:N17)) -> 0.8295277 | O18: =IF(O17="","",AVERAGE($I14:O17)) -> 0.83042999 | P18: =IF(P17="","",AVERAGE($I14:P17)) -> 0.82611488 | ... FF18: =IF(FF17="","",AVERAGE($I14:FF17)) -> 0.89188588 | FG18: =IF(FG17="","",AVERAGE($FG14:FG17)) -> 0.95797619 | FH18: =IF(FH17="","",AVERAGE($FG14:FH17)) -> 0.93960658 | FI18: =IF(FI17="","",AVERAGE($FG14:FI17)) -> 0.93620763 | FJ18: =IF(FJ17="","",AVERAGE($FG14:FJ17)) -> 0.9332651 | FK18: =IF(FK17="","",AVERAGE($FG14:FK17)) -> 0.93153443 | FL18: =IF(FL17="","",AVERAGE($FG14:FL17)) -> 0.93122805 | FM18: =IF(FM17="","",AVERAGE($FG14:FM17)) -> 0.93147844 | FN18: =IF(FN17="","",AVERAGE(FN14:FN17)) -> 0.93776786 | FO18: =IF(FO17="","",AVERAGE(FN14:FO17)) -> 0.93825546 | FP18: =IF(FP17="","",AVERAGE(FN14:FP17)) -> 0.93649756 | FQ18: =IF(FQ17="","",AVERAGE(FN14:FQ17)) -> 0.93660418 | FR18: =IF(FR17="","",AVERAGE(FN14:FR17)) -> 0.93672431 | FS18: =IF(FS17="","",AVERAGE(FN14:FS17)) -> 0.93735524 | FT18: =IF(FT17="","",AVERAGE(FN14:FT17)) -> 0.93817428 | FU18: =IF(FU17="","",AVERAGE(FU14:FU17)) -> 0.94579861 | FV18: =IF(FV17="","",AVERAGE(FU14:FV17)) -> 0.94274542 | FW18: =IF(FW17="","",AVERAGE(FU14:FW17)) -> 0.93676235 | FX18: =IF(FX17="","",AVERAGE(FU14:FX17)) -> 0.93455418 | FY18: =IF(FY17="","",AVERAGE(FU14:FY17)) -> 0.93337835 | FZ18: =IF(FZ17="","",AVERAGE(FU14:FZ17)) -> 0.93216892 | GA18: =IF(GA17="","",AVERAGE(FU14:GA17)) -> 0.93153555 | GB18: =IF(GB17="","",AVERAGE(GB14:GB17)) -> 0.93031622 | GC18: =IF(GC17="","",AVERAGE(GB14:GC17)) -> 0.93148534 | GD18: =IF(GD17="","",AVERAGE(GB14:GD17)) -> 0.9279011 | GE18: =IF(GE17="","",AVERAGE(GB14:GE17)) -> 0.88777479 | GF18: =IF(GF17="","",AVERAGE(GB14:GF17)) -> 0.88695941 | GG18: =IF(GG17="","",AVERAGE(GB14:GG17)) -> 0.89287706 | GH18: =IF(GH17="","",AVERAGE(GB14:GH17)) -> 0.89896158 | GI18: =IF(GI17="","",AVERAGE(GI14:GI17)) -> 0.9233125 | GJ18: =IF(GJ17="","",AVERAGE(GI14:GJ17)) -> 0.92826215 | GK18: =IF(GK17="","",AVERAGE(GI14:GK17)) -> 0.93309243 | GL18: =IF(GL17="","",AVERAGE(GI14:GL17)) -> 0.93559406 | GM18: =IF(GM17="","",AVERAGE(GI14:GM17)) -> 0.93734562 | GN18: =IF(GN17="","",AVERAGE(GI14:GN17)) -> 0.93834357 | GO18: =IF(GO17="","",AVERAGE(GI14:GO17)) -> 0.93979232 | GP18: =IF(GP17="","",AVERAGE(GP14:GP17)) -> 0.95277778 | GQ18: =IF(GQ17="","",AVERAGE(GP14:GQ17)) -> 0.95459402 | GR18: =IF(GR17="","",AVERAGE(GP14:GR17)) -> 0.95623728 | GS18: =IF(GS17="","",AVERAGE(GP14:GS17)) -> 0.95773352 | GT18: =IF(GT17="","",AVERAGE(GP14:GT17)) -> 0.95868681 | GU18: =IF(GU17="","",AVERAGE(GP14:GU17)) -> 0.95885972 | GV18: =IF(GV17="","",AVERAGE(GP14:GV17)) -> 0.95930288 | GW18: =IF(GW17="","",AVERAGE(GW14:GW17)) -> 0.95987939 | GX18: =IF(GX17="","",AVERAGE(GW14:GX17)) -> 0.9608824 | GY18: =IF(GY17="","",AVERAGE(GW14:GY17)) -> 0.93646624 | GZ18: =IF(GZ17="","",AVERAGE(GW14:GZ17)) -> 0.92463306 | HA18: =IF(HA17="","",AVERAGE(GW14:HA17)) -> 0.91849721 | HB18: =IF(HB17="","",AVERAGE(GW14:HB17)) -> 0.91514308 | HC18: =IF(HC17="","",AVERAGE(GW14:HC17)) -> 0.91332799 | HD18: =IF(HD17="","",AVERAGE(HD14:HD17)) -> 0.9061899 | HE18: =IF(HE17="","",AVERAGE(HD14:HE17)) -> 0.87993716 | HF18: =IF(HF17="","",AVERAGE(HD14:HF17)) -> 0.8729281 | HG18: =IF(HG17="","",AVERAGE(HD14:HG17)) -> 0.87063986 | HH18: =IF(HH17="","",AVERAGE(HD14:HH17)) -> 0.87017508 | HI18: =IF(HI17="","",AVERAGE(HD14:HI17)) -> 0.87057321 | HJ18: =IF(HJ17="","",AVERAGE(HD14:HJ17)) -> 0.88906275 | HK18: =IF(HK17="","",AVERAGE($I14:HK17)) -> 0.90124112 | HL18: =IF(HL17="","",AVERAGE($I14:HL17)) -> 0.90170696 | HM18: =IF(HM17="","",AVERAGE($I14:HM17)) -> 0.90216763 | HN18: =IF(HN17="","",AVERAGE($I14:HN17)) -> 0.90241612 | HO18: =IF(HO17="","",AVERAGE($I14:HO17)) -> 0.90250311 | HP18: =IF(HP17="","",AVERAGE($I14:HP17)) -> 0.90244547 | HQ18: =IF(HQ17="","",AVERAGE($I14:HQ17)) -> 0.9024376 | HR18: =IF(HR17="","",AVERAGE($I14:HR17)) -> 0.90248038 | ... OZ18: =IF(OZ17="","",AVERAGE($I14:OZ17))
A19: =ISODD(B19) -> FALSE | B19: 16 | C19: =C17 -> Mechanical Availability | D19: =D17 -> 777 Optiload | E19: Overall MTD | F19: =IF('All Fleet'!C50="","",'All Fleet'!C50) -> 1 | G19: =IF('All Fleet'!D50="","",'All Fleet'!D50) -> 0.718125 | H19: =IF('All Fleet'!E50="","",'All Fleet'!E50) -> 0.79802083 | I19: =IF('All Fleet'!F50="","",'All Fleet'!F50) -> 0.84851562 | J19: =IF('All Fleet'!G50="","",'All Fleet'!G50) -> 0.8148125 | K19: =IF('All Fleet'!H50="","",'All Fleet'!H50) -> 0.8259375 | L19: =IF('All Fleet'!I50="","",'All Fleet'!I50) -> 0.83619048 | M19: =IF('All Fleet'!J50="","",'All Fleet'!J50) -> 0.81778646 | ... OZ19: =IF('All Fleet'!OW50="","",'All Fleet'!OW50)
A20: =ISODD(B20) -> TRUE | B20: 17 | C20: =C19 -> Mechanical Availability | D20: =D19 -> 777 Optiload | E20: Overall YTD | F20: =IF('All Fleet'!C63="","",'All Fleet'!C63) -> 1 | G20: =IF('All Fleet'!D63="","",'All Fleet'!D63) -> 0.718125 | H20: =IF('All Fleet'!E63="","",'All Fleet'!E63) -> 0.79802083 | I20: =IF('All Fleet'!F63="","",'All Fleet'!F63) -> 0.84851562 | J20: =IF('All Fleet'!G63="","",'All Fleet'!G63) -> 0.8148125 | K20: =IF('All Fleet'!H63="","",'All Fleet'!H63) -> 0.8259375 | L20: =IF('All Fleet'!I63="","",'All Fleet'!I63) -> 0.83619048 | M20: =IF('All Fleet'!J63="","",'All Fleet'!J63) -> 0.81778646 | ... OZ20: =IF('All Fleet'!OW63="","",'All Fleet'!OW63)
A21: =ISODD(B21) -> FALSE | B21: 18 | C21: =C20 -> Mechanical Availability | D21: =D20 -> 777 Optiload | E21: Quota Monthly (hrs) | F21: =IF('All Fleet'!C76="","",(((COUNTIFS('All Fleet'!$A$66:$A$74,"777")*'All Fleet'!C$5)*11.8%))-'All Fleet'!C76) -> 11.328 | G21: =IF('All Fleet'!D76="","",(((COUNTIFS('All Fleet'!$A$66:$A$74,"777")*'All Fleet'!D$5)*11.8%))-'All Fleet'!D76) -> -31.464 | H21: =IF('All Fleet'!E76="","",(((COUNTIFS('All Fleet'!$A$66:$A$74,"777")*'All Fleet'!E$5)*11.8%))-'All Fleet'!E76) -> -24.186 | I21: =IF('All Fleet'!F76="","",(((COUNTIFS('All Fleet'!$A$66:$A$74,"777")*'All Fleet'!F$5)*11.8%))-'All Fleet'!F76) -> -12.858 | J21: =IF('All Fleet'!G76="","",(((COUNTIFS('All Fleet'!$A$66:$A$74,"777")*'All Fleet'!G$5)*11.8%))-'All Fleet'!G76) -> -32.25 | K21: =IF('All Fleet'!H76="","",(((COUNTIFS('All Fleet'!$A$66:$A$74,"777")*'All Fleet'!H$5)*11.8%))-'All Fleet'!H76) -> -32.292 | L21: =IF('All Fleet'!I76="","",(((COUNTIFS('All Fleet'!$A$66:$A$74,"777")*'All Fleet'!I$5)*11.8%))-'All Fleet'!I76) -> -30.784 | M21: =IF('All Fleet'!J76="","",(((COUNTIFS('All Fleet'!$A$66:$A$74,"777")*'All Fleet'!J$5)*11.8%))-'All Fleet'!J76) -> -49.316 | ... OZ21: =IF('All Fleet'!OW76="","",(((COUNTIFS('All Fleet'!$A$66:$A$74,"777")*'All Fleet'!OW$5)*11.8%))-'All Fleet'!OW76)
A22: =ISODD(B22) -> TRUE | B22: 19 | C22: =C21 -> Mechanical Availability | D22: =D21 -> 777 Optiload | E22: Quota Daily (hrs) | F22: =IF('All Fleet'!C76="","",(5*24*11.8%)-'All Fleet'!C23) -> 14.16 | G22: =IF('All Fleet'!D76="","",(5*24*11.8%)-'All Fleet'!D23) -> -39.96 | H22: =IF('All Fleet'!E76="","",(5*24*11.8%)-'All Fleet'!E23) -> 10.11 | I22: =IF('All Fleet'!F76="","",(5*24*11.8%)-'All Fleet'!F23) -> 14.16 | J22: =IF('All Fleet'!G76="","",(5*24*11.8%)-'All Fleet'!G23) -> -16.56 | K22: =IF('All Fleet'!H76="","",(5*24*11.8%)-'All Fleet'!H23) -> 2.79 | L22: =IF('All Fleet'!I76="","",(5*24*11.8%)-'All Fleet'!I23) -> 4.34 | M22: =IF('All Fleet'!J76="","",(5*24*11.8%)-'All Fleet'!J23) -> -15.7 | ... OZ22: =IF('All Fleet'!OW76="","",(5*24*11.8%)-'All Fleet'!OW23)
